Workbook

Sheet BPP Resto
A1: Perhitungan Bpp Resto
C2: Pembungus | D2: Free
B3: IceCampur | C3: FALSE | E3: Air Mineral
B4: Rice Bowl & Mie | C4: FALSE
B7: NAMA BARANG | E7: RESEP BAHAN | I7: HARGA LAMA | O7: HARGA BARU
B8: Kode Barang Grup | C8: Nama Barang | E8: Kode Rincian Grup | F8: Nama Barang | G8: KTS | H8: Satuan | I8: SHS | J8: Harga Per Kg | K8: Total BPP | L8: % Bpp | M8: KEUNTUNGAN | N8: % keuntungan | O8: SHS | P8: Total BPP | Q8: % Bpp | R8: Profit | S8: % Profit
A9: ES CAMPUR MONSTERS | B9: CPR.0001 NEW | C9: ICE CAMPUR1 PORSI | D9: =IFERROR(VLOOKUP(B9, 'Database Resto'!C:P, 9, FALSE),"") -> 19900 | E9: MNMN.30102 | F9: Buah Naga | G9: 80 | H9: Gram | I9: =IFERROR(VLOOKUP(E9, 'Database Resto'!C:P, 13, FALSE),"") -> 30.018483 | J9: =I9*1000 -> 30018.483 | K9: =IFERROR(VLOOKUP(E9, 'Database Resto'!C:P, 13, FALSE)* G9, 0) -> 2401.4786 | L9: =IF(D9="","", IFERROR(IF(B9="", K9/D9, SUMIFS($K:$K, $B:$B, B9)/D9), "")) -> 0.60244579 | M9: =D9-SUM(K9:K17) -> 7911.3288 | N9: =IFERROR(M9/D9, ) -> 0.39755421 | O9: {=IF(E9:E396="","",IFERROR(VLOOKUP(E9:E396,'Harga Bpp Resto'!B:N,9,FALSE),""))} -> 36.022179 | P9: =IF(O9=0, G9*I9, G9*O9) -> 2881.7744 | Q9: =IF(D9="","", IFERROR(SUMIFS($P:$P, $B:$B, B9)/D9, 0)) -> 0.66449273 | R9: =IF(D9="","", D9 - SUMIFS($P:$P, $B:$B, B9)) -> 6676.5946 | S9: =IFERROR(R9/D9, ) -> 0.33550727
B10: CPR.0001 NEW | E10: MNMN.30109 | F10: Gula Es Campur | G10: 95 | H10: Gram | I10: =IFERROR(VLOOKUP(E10, 'Database Resto'!C:P, 13, FALSE),"") -> 25 | J10: =I10*1000 -> 25000 | K10: =IFERROR(VLOOKUP(E10, 'Database Resto'!C:P, 13, FALSE)* G10, 0) -> 2375 | P10: =IF(O10=0, G10*I10, G10*O10) -> 2375
B11: CPR.0001 NEW | E11: MNMN.30112 | F11: K. Hijau | G11: 80 | H11: Gram | I11: =IFERROR(VLOOKUP(E11, 'Database Resto'!C:P, 13, FALSE),"") -> 18 | J11: =I11*1000 -> 18000 | K11: =IFERROR(VLOOKUP(E11, 'Database Resto'!C:P, 13, FALSE)* G11, 0) -> 1440 | P11: =IF(O11=0, G11*I11, G11*O11) -> 1440
B12: CPR.0001 NEW | E12: MNMN.30113 | F12: K. Merah | G12: 80 | H12: Gram | I12: =IFERROR(VLOOKUP(E12, 'Database Resto'!C:P, 13, FALSE),"") -> 25 | J12: =I12*1000 -> 25000 | K12: =IFERROR(VLOOKUP(E12, 'Database Resto'!C:P, 13, FALSE)* G12, 0) -> 2000 | P12: =IF(O12=0, G12*I12, G12*O12) -> 2000
B13: CPR.0001 NEW | E13: MNMN.30115 | F13: Melon | G13: 80 | H13: Gram | I13: =IFERROR(VLOOKUP(E13, 'Database Resto'!C:P, 13, FALSE),"") -> 25.23528 | J13: =I13*1000 -> 25235.28 | K13: =IFERROR(VLOOKUP(E13, 'Database Resto'!C:P, 13, FALSE)* G13, 0) -> 2018.8224 | O13: 30.282336 | P13: =IF(O13=0, G13*I13, G13*O13) -> 2422.5869
B14: CPR.0001 NEW | E14: MNMN.30120 | F14: Semangka | G14: 80 | H14: Gram | I14: =IFERROR(VLOOKUP(E14, 'Database Resto'!C:P, 13, FALSE),"") -> 21.917127 | J14: =I14*1000 -> 21917.127 | K14: =IFERROR(VLOOKUP(E14, 'Database Resto'!C:P, 13, FALSE)* G14, 0) -> 1753.3701 | O14: 26.300552 | P14: =IF(O14=0, G14*I14, G14*O14) -> 2104.0442
B15: CPR.0001 NEW | E15: =IFERROR(__xludf.DUMMYFUNCTION("IF(C3, FILTER(Pembungkus!B:E, Pembungkus!A:A=""Ice Campur""), """")"),"") | I15: =IFERROR(VLOOKUP(E15, 'Database Resto'!C:P, 13, FALSE),"") | J15: =I15 | K15: =IFERROR(VLOOKUP(E15, 'Database Resto'!C:P, 13, FALSE)* G15, 0) -> 0 | P15: =IF(O15=0, G15*I15, G15*O15) -> 0
B17: CPR.0001 NEW | I17: =IFERROR(VLOOKUP(E17, 'Database Resto'!C:P, 13, FALSE),"") | J17: =I17 | K17: =IFERROR(VLOOKUP(E17, 'Database Resto'!C:P, 13, FALSE)* G17, 0) -> 0 | P17: =IF(O17=0, G17*I17, G17*O17) -> 0
D18: =SUM(D9:D17) -> 19900 | I18: =IFERROR(VLOOKUP(E18, 'Database Resto'!C:P, 13, FALSE),"") | K18: =SUM(K9:K17) -> 11988.671 | L18: =IFERROR(K18/D9, 0) -> 0.60244579 | M18: =D9-K18 -> 7911.3288 | N18: =IFERROR(M18/D18, ) -> 0.39755421 | P18: =SUM(P9:P17) -> 13223.405 | Q18: =IFERROR(P18/D9, 0) -> 0.66449273 | R18: =D9-P18 -> 6676.5946 | S18: =IFERROR(R18/D18, ) -> 0.33550727
B19: CPR.0002 NEW | C19: ICE CAMPUR 2 PORSI | D19: =IFERROR(VLOOKUP(B19, 'Database Resto'!C:P, 9, FALSE),"") -> 37000 | E19: MNMN.30102 | F19: Buah Naga | G19: 160 | H19: Gram | I19: =IFERROR(VLOOKUP(E19, 'Database Resto'!C:P, 13, FALSE),"") -> 30.018483 | J19: =I19*1000 -> 30018.483 | K19: =IFERROR(VLOOKUP(E19, 'Database Resto'!C:P, 13, FALSE)* G19, 0) -> 4802.9573 | L19: =IF(D19="","", IFERROR(IF(B19="", K19/D19, SUMIFS($K:$K, $B:$B, B19)/D19), "")) -> 0.64803628 | M19: =D19-SUM(K19:K24) -> 13022.658 | N19: =IFERROR(M19/D19, ) -> 0.35196372 | O19: 36.022179 | Q19: =IF(D19="","", IFERROR(SUMIFS($P:$P, $B:$B, B19)/D19, 0)) -> 0.55900708 | R19: =IF(D19="","", D19 - SUMIFS($P:$P, $B:$B, B19)) -> 16316.738 | S19: =IFERROR(R19/D19, ) -> 0.44099292
B20: CPR.0002 NEW | E20: MNMN.30109 | F20: Gula Es Campur | G20: 190 | H20: Gram | I20: =IFERROR(VLOOKUP(E20, 'Database Resto'!C:P, 13, FALSE),"") -> 25 | J20: =I20*1000 -> 25000 | K20: =IFERROR(VLOOKUP(E20, 'Database Resto'!C:P, 13, FALSE)* G20, 0) -> 4750 | P20: =IF(O20=0, G20*I20, G20*O20) -> 4750
B21: CPR.0002 NEW | E21: MNMN.30112 | F21: K. Hijau | G21: 160 | H21: Gram | I21: =IFERROR(VLOOKUP(E21, 'Database Resto'!C:P, 13, FALSE),"") -> 18 | J21: =I21*1000 -> 18000 | K21: =IFERROR(VLOOKUP(E21, 'Database Resto'!C:P, 13, FALSE)* G21, 0) -> 2880 | P21: =IF(O21=0, G21*I21, G21*O21) -> 2880
B22: CPR.0002 NEW | E22: MNMN.30113 | F22: K. Merah | G22: 160 | H22: Gram | I22: =IFERROR(VLOOKUP(E22, 'Database Resto'!C:P, 13, FALSE),"") -> 25 | J22: =I22*1000 -> 25000 | K22: =IFERROR(VLOOKUP(E22, 'Database Resto'!C:P, 13, FALSE)* G22, 0) -> 4000 | P22: =IF(O22=0, G22*I22, G22*O22) -> 4000
B23: CPR.0002 NEW | E23: MNMN.30115 | F23: Melon | G23: 160 | H23: Gram | I23: =IFERROR(VLOOKUP(E23, 'Database Resto'!C:P, 13, FALSE),"") -> 25.23528 | J23: =I23*1000 -> 25235.28 | K23: =IFERROR(VLOOKUP(E23, 'Database Resto'!C:P, 13, FALSE)* G23, 0) -> 4037.6448 | O23: 30.282336 | P23: =IF(O23=0, G23*I23, G23*O23) -> 4845.1737
B24: CPR.0002 NEW | E24: MNMN.30120 | F24: Semangka | G24: 160 | H24: Gram | I24: =IFERROR(VLOOKUP(E24, 'Database Resto'!C:P, 13, FALSE),"") -> 21.917127 | J24: =I24*1000 -> 21917.127 | K24: =IFERROR(VLOOKUP(E24, 'Database Resto'!C:P, 13, FALSE)* G24, 0) -> 3506.7403 | O24: 26.300552 | P24: =IF(O24=0, G24*I24, G24*O24) -> 4208.0883
C25: ICE CAMPUR 2 PORSI | D25: =SUM(D19:D24) -> 37000 | I25: =IFERROR(VLOOKUP(E25, 'Database Resto'!C:P, 13, FALSE),"") | K25: =SUM(K19:K24) -> 23977.342 | L25: =IFERROR(K25/D19, 0) -> 0.64803628 | M25: =D19-K25 -> 13022.658 | N25: =IFERROR(M25/D25, ) -> 0.35196372 | P25: =SUM(P19:P24) -> 20683.262 | Q25: =IFERROR(P25/D19, 0) -> 0.55900708 | R25: =D19-P25 -> 16316.738 | S25: =IFERROR(R25/D25, ) -> 0.44099292
B26: CPR.0003 NEW | C26: ICE CAMPUR 4 PORSI | D26: =IFERROR(VLOOKUP(B26, 'Database Resto'!C:P, 9, FALSE),"") -> 71900 | E26: MNMN.30102 | F26: Buah Naga | G26: 320 | H26: Gram | I26: =IFERROR(VLOOKUP(E26, 'Database Resto'!C:P, 13, FALSE),"") -> 30.018483 | J26: =I26*1000 -> 30018.483 | K26: =IFERROR(VLOOKUP(E26, 'Database Resto'!C:P, 13, FALSE)* G26, 0) -> 9605.9145 | L26: =IF(D26="","", IFERROR(IF(B26="", K26/D26, SUMIFS($K:$K, $B:$B, B26)/D26), "")) -> 0.66696363 | M26: =D26-SUM(K26:K31) -> 23945.315 | N26: =IFERROR(M26/D26, ) -> 0.33303637 | O26: 36.022179 | P26: =IF(O26=0, G26*I26, G26*O26) -> 11527.097 | Q26: =IF(D26="","", IFERROR(SUMIFS($P:$P, $B:$B, B26)/D26, 0)) -> 0.73565538 | R26: =IF(D26="","", D26 - SUMIFS($P:$P, $B:$B, B26)) -> 19006.378 | S26: =IFERROR(R26/D26, ) -> 0.26434462
B27: CPR.0003 NEW | E27: MNMN.30109 | F27: Gula Es Campur | G27: 380 | H27: Gram | I27: =IFERROR(VLOOKUP(E27, 'Database Resto'!C:P, 13, FALSE),"") -> 25 | J27: =I27*1000 -> 25000 | K27: =IFERROR(VLOOKUP(E27, 'Database Resto'!C:P, 13, FALSE)* G27, 0) -> 9500 | P27: =IF(O27=0, G27*I27, G27*O27) -> 9500
B28: CPR.0003 NEW | E28: MNMN.30112 | F28: K. Hijau | G28: 320 | H28: Gram | I28: =IFERROR(VLOOKUP(E28, 'Database Resto'!C:P, 13, FALSE),"") -> 18 | J28: =I28*1000 -> 18000 | K28: =IFERROR(VLOOKUP(E28, 'Database Resto'!C:P, 13, FALSE)* G28, 0) -> 5760 | P28: =IF(O28=0, G28*I28, G28*O28) -> 5760
B29: CPR.0003 NEW | E29: MNMN.30113 | F29: K. Merah | G29: 320 | H29: Gram | I29: =IFERROR(VLOOKUP(E29, 'Database Resto'!C:P, 13, FALSE),"") -> 25 | J29: =I29*1000 -> 25000 | K29: =IFERROR(VLOOKUP(E29, 'Database Resto'!C:P, 13, FALSE)* G29, 0) -> 8000 | P29: =IF(O29=0, G29*I29, G29*O29) -> 8000
B30: CPR.0003 NEW | E30: MNMN.30115 | F30: Melon | G30: 320 | H30: Gram | I30: =IFERROR(VLOOKUP(E30, 'Database Resto'!C:P, 13, FALSE),"") -> 25.23528 | J30: =I30*1000 -> 25235.28 | K30: =IFERROR(VLOOKUP(E30, 'Database Resto'!C:P, 13, FALSE)* G30, 0) -> 8075.2896 | O30: 30.282336 | P30: =IF(O30=0, G30*I30, G30*O30) -> 9690.3475
B31: CPR.0003 NEW | E31: MNMN.30120 | F31: Semangka | G31: 320 | H31: Gram | I31: =IFERROR(VLOOKUP(E31, 'Database Resto'!C:P, 13, FALSE),"") -> 21.917127 | J31: =I31*1000 -> 21917.127 | K31: =IFERROR(VLOOKUP(E31, 'Database Resto'!C:P, 13, FALSE)* G31, 0) -> 7013.4806 | O31: 26.300552 | P31: =IF(O31=0, G31*I31, G31*O31) -> 8416.1767
C32: ICE CAMPUR 4 PORSI | D32: =SUM(D26:D31) -> 71900 | I32: =IFERROR(VLOOKUP(E32, 'Database Resto'!C:P, 13, FALSE),"") | J32: 0 | K32: =SUM(K26:K31) -> 47954.685 | L32: =IFERROR(K32/D26, 0) -> 0.66696363 | M32: =D26-K32 -> 23945.315 | N32: =IFERROR(M32/D32, ) -> 0.33303637 | P32: =SUM(P26:P31) -> 52893.622 | Q32: =IFERROR(P32/D26, 0) -> 0.73565538 | R32: =D26-P32 -> 19006.378 | S32: =IFERROR(R32/D32, ) -> 0.26434462
B33: CPR.0004 NEW | C33: ICE CAMPUR 8 PORSI | D33: =IFERROR(VLOOKUP(B33, 'Database Resto'!C:P, 9, FALSE),"") -> 135900 | E33: MNMN.30102 | F33: Buah Naga | G33: 640 | H33: Gram | I33: =IFERROR(VLOOKUP(E33, 'Database Resto'!C:P, 13, FALSE),"") -> 30.018483 | J33: =I33*1000 -> 30018.483 | K33: =IFERROR(VLOOKUP(E33, 'Database Resto'!C:P, 13, FALSE)* G33, 0) -> 19211.829 | L33: =IF(D33="","", IFERROR(IF(B33="", K33/D33, SUMIFS($K:$K, $B:$B, B33)/D33), "")) -> 0.70573487 | M33: =D33-SUM(K33:K38) -> 39990.631 | N33: =IFERROR(M33/D33, ) -> 0.29426513 | O33: 36.022179 | P33: =IF(O33=0, G33*I33, G33*O33) -> 23054.195 | Q33: =IF(D33="","", IFERROR(SUMIFS($P:$P, $B:$B, B33)/D33, 0)) -> 0.77841974 | R33: =IF(D33="","", D33 - SUMIFS($P:$P, $B:$B, B33)) -> 30112.757 | S33: =IFERROR(R33/D33, ) -> 0.22158026
B34: CPR.0004 NEW | E34: MNMN.30109 | F34: Gula Es Campur | G34: 760 | H34: Gram | I34: =IFERROR(VLOOKUP(E34, 'Database Resto'!C:P, 13, FALSE),"") -> 25 | J34: =I34*1000 -> 25000 | K34: =IFERROR(VLOOKUP(E34, 'Database Resto'!C:P, 13, FALSE)* G34, 0) -> 19000 | P34: =IF(O34=0, G34*I34, G34*O34) -> 19000
B35: CPR.0004 NEW | E35: MNMN.30112 | F35: K. Hijau | G35: 640 | H35: Gram | I35: =IFERROR(VLOOKUP(E35, 'Database Resto'!C:P, 13, FALSE),"") -> 18 | J35: =I35*1000 -> 18000 | K35: =IFERROR(VLOOKUP(E35, 'Database Resto'!C:P, 13, FALSE)* G35, 0) -> 11520 | P35: =IF(O35=0, G35*I35, G35*O35) -> 11520
B36: CPR.0004 NEW | E36: MNMN.30113 | F36: K. Merah | G36: 640 | H36: Gram | I36: =IFERROR(VLOOKUP(E36, 'Database Resto'!C:P, 13, FALSE),"") -> 25 | J36: =I36*1000 -> 25000 | K36: =IFERROR(VLOOKUP(E36, 'Database Resto'!C:P, 13, FALSE)* G36, 0) -> 16000 | P36: =IF(O36=0, G36*I36, G36*O36) -> 16000
B37: CPR.0004 NEW | E37: MNMN.30115 | F37: Melon | G37: 640 | H37: Gram | I37: =IFERROR(VLOOKUP(E37, 'Database Resto'!C:P, 13, FALSE),"") -> 25.23528 | J37: =I37*1000 -> 25235.28 | K37: =IFERROR(VLOOKUP(E37, 'Database Resto'!C:P, 13, FALSE)* G37, 0) -> 16150.579 | O37: 30.282336 | P37: =IF(O37=0, G37*I37, G37*O37) -> 19380.695
B38: CPR.0004 NEW | E38: MNMN.30120 | F38: Semangka | G38: 640 | H38: Gram | I38: =IFERROR(VLOOKUP(E38, 'Database Resto'!C:P, 13, FALSE),"") -> 21.917127 | J38: =I38*1000 -> 21917.127 | K38: =IFERROR(VLOOKUP(E38, 'Database Resto'!C:P, 13, FALSE)* G38, 0) -> 14026.961 | O38: 26.300552 | P38: =IF(O38=0, G38*I38, G38*O38) -> 16832.353
D39: =IFERROR(VLOOKUP(B39, 'Database Resto'!C:P, 9, FALSE),"") | I39: =IFERROR(VLOOKUP(E39, 'Database Resto'!C:P, 13, FALSE),"") | J39: =I39*1000 -> 0 | K39: =SUM(K33:K38) -> 95909.369 | L39: =IFERROR(K39/D33, 0) -> 0.70573487 | M39: =D33-K39 -> 39990.631 | N39: =IFERROR(M39/D39, ) | P39: =SUM(P33:P38) -> 105787.24 | Q39: =IFERROR(P39/D33, 0) -> 0.77841974 | R39: =D33-P39 -> 30112.757 | S39: =IFERROR(R39/D39, )
B40: CPR.0005 NEW | C40: ICE CAMPUR10 PORSI | D40: =IFERROR(VLOOKUP(B40, 'Database Resto'!C:P, 9, FALSE),"") -> 160000 | E40: MNMN.30102 | F40: Buah Naga | G40: 800 | H40: Gram | I40: =IFERROR(VLOOKUP(E40, 'Database Resto'!C:P, 13, FALSE),"") -> 30.018483 | J40: =I40*1000 -> 30018.483 | K40: =IFERROR(VLOOKUP(E40, 'Database Resto'!C:P, 13, FALSE)* G40, 0) -> 24014.786 | L40: =IF(D40="","", IFERROR(IF(B40="", K40/D40, SUMIFS($K:$K, $B:$B, B40)/D40), "")) -> 0.74929195 | M40: =D40-SUM(K40:K45) -> 40113.288 | N40: =IFERROR(M40/D40, ) -> 0.25070805 | O40: 36.022179 | P40: =IF(O40=0, G40*I40, G40*O40) -> 28817.744 | Q40: =IF(D40="","", IFERROR(SUMIFS($P:$P, $B:$B, B40)/D40, 0)) -> 0.82646284 | R40: =IF(D40="","", D40 - SUMIFS($P:$P, $B:$B, B40)) -> 27765.946 | S40: =IFERROR(R40/D40, ) -> 0.17353716
B41: CPR.0005 NEW | E41: MNMN.30109 | F41: Gula Es Campur | G41: 950 | H41: Gram | I41: =IFERROR(VLOOKUP(E41, 'Database Resto'!C:P, 13, FALSE),"") -> 25 | J41: =I41*1000 -> 25000 | K41: =IFERROR(VLOOKUP(E41, 'Database Resto'!C:P, 13, FALSE)* G41, 0) -> 23750 | P41: =IF(O41=0, G41*I41, G41*O41) -> 23750
B42: CPR.0005 NEW | E42: MNMN.30112 | F42: K. Hijau | G42: 800 | H42: Gram | I42: =IFERROR(VLOOKUP(E42, 'Database Resto'!C:P, 13, FALSE),"") -> 18 | J42: =I42*1000 -> 18000 | K42: =IFERROR(VLOOKUP(E42, 'Database Resto'!C:P, 13, FALSE)* G42, 0) -> 14400 | P42: =IF(O42=0, G42*I42, G42*O42) -> 14400
B43: CPR.0005 NEW | E43: MNMN.30113 | F43: K. Merah | G43: 800 | H43: Gram | I43: =IFERROR(VLOOKUP(E43, 'Database Resto'!C:P, 13, FALSE),"") -> 25 | J43: =I43*1000 -> 25000 | K43: =IFERROR(VLOOKUP(E43, 'Database Resto'!C:P, 13, FALSE)* G43, 0) -> 20000 | P43: =IF(O43=0, G43*I43, G43*O43) -> 20000
...

Sheet BPP Dapur
C1: Laporan Hpp Dapur
A5: Nama | B5: Harga | C5: QTY Jual | E5: Satuan Jual | F5: Rincian | G5: Qty | H5: Satuan | I5: Barang Jadi | J5: Satuan | K5: Kompres | O5: Rincian Harga | P5: BPP Per Jual | Q5: Perhitungan Harga Lama | T5: Satuan | U5: Perhitungan Harga Baru | X5: Atur Harga
C6: kompres Gr | D6: QTY Jual | K6: Satuan | L6: QTY /GR | M6: Harga Satuan | N6: Harga /KG | Q6: Laba | R6: Persentase | S6: Harga Jual Lama | U6: Harga Jual Baru | V6: Laba | W6: Persentase
A7: Saus Asam Manis | B7: =IFERROR(VLOOKUP(A7, 'Database Dapur'!C:D, 2, FALSE),"") -> 27000 | C7: =D7*1000 -> 1000 | D7: 1 | E7: =IFERROR(VLOOKUP(A7, 'Database Dapur'!C:F, 3, FALSE),"") -> Kg | F7: Sauce Sambal ABC @24kg | G7: 35 | H7: Gram | I7: 1000 | J7: Gram | K7: Kg | L7: 1000 | M7: {=IFERROR((_xlfn.XLOOKUP(TRIM(F7), TRIM('Database Dapur'!C:C), 'Database Dapur'!D:D)),"")} -> 26765 | N7: {=IFERROR((_xlfn.XLOOKUP(TRIM(F7), TRIM('Database Dapur'!C:C), 'Database Dapur'!D:D) / L7),"")*1000} -> 26765 | O7: {=IFERROR((_xlfn.XLOOKUP(TRIM(F7), TRIM('Database Dapur'!C:C), 'Database Dapur'!D:D) / L7) * G7, "")} -> 936.775 | P7: =O14/I7*C7 -> 15260.176 | Q7: =B7-P7 -> 11739.824 | R7: =(P7/B7) -> 0.56519171 | S7: =IFERROR(VLOOKUP(A7, 'Database Dapur'!C:D, 2, FALSE),"") -> 27000 | T7: =IFERROR(VLOOKUP(A7, 'Database Dapur'!C:F, 3, FALSE),"") -> Kg | U7: =S7-X7 -> 27000 | V7: =U7-P7 -> 11739.824 | W7: =(P7/U7) -> 0.56519171
F8: Gula Pasir | G8: 200 | H8: Gram | K8: Kg | L8: 1000 | M8: {=IFERROR((_xlfn.XLOOKUP(TRIM(F8), TRIM('Database Dapur'!C:C), 'Database Dapur'!D:D)),"")} -> 17200 | N8: {=IFERROR((_xlfn.XLOOKUP(TRIM(F8), TRIM('Database Dapur'!C:C), 'Database Dapur'!D:D) / L8),"")*1000} -> 17200 | O8: {=IFERROR((_xlfn.XLOOKUP(TRIM(F8), TRIM('Database Dapur'!C:C), 'Database Dapur'!D:D) / L8) * G8, "")} -> 3440
F9: Garam | G9: 10 | H9: Gram | K9: Kg | L9: 1000 | M9: {=IFERROR((_xlfn.XLOOKUP(TRIM(F9), TRIM('Database Dapur'!C:C), 'Database Dapur'!D:D)),"")} -> 6100 | N9: {=IFERROR((_xlfn.XLOOKUP(TRIM(F9), TRIM('Database Dapur'!C:C), 'Database Dapur'!D:D) / L9),"")*1000} -> 6100 | O9: {=IFERROR((_xlfn.XLOOKUP(TRIM(F9), TRIM('Database Dapur'!C:C), 'Database Dapur'!D:D) / L9) * G9, "")} -> 61
F10: Cuka Dixi @650ml | G10: 5 | H10: Gram | K10: Botol | L10: 650 | M10: {=IFERROR((_xlfn.XLOOKUP(TRIM(F10), TRIM('Database Dapur'!C:C), 'Database Dapur'!D:D)),"")} -> 15000 | N10: {=IFERROR((_xlfn.XLOOKUP(TRIM(F10), TRIM('Database Dapur'!C:C), 'Database Dapur'!D:D) / L10),"")*1000} -> 23076.923 | O10: {=IFERROR((_xlfn.XLOOKUP(TRIM(F10), TRIM('Database Dapur'!C:C), 'Database Dapur'!D:D) / L10) * G10, "")} -> 115.38462
F11: Plum Sauce @7ltr | G11: 50 | H11: Gram | K11: Pack | L11: 7000 | M11: {=IFERROR((_xlfn.XLOOKUP(TRIM(F11), TRIM('Database Dapur'!C:C), 'Database Dapur'!D:D)),"")} -> 550000 | N11: {=IFERROR((_xlfn.XLOOKUP(TRIM(F11), TRIM('Database Dapur'!C:C), 'Database Dapur'!D:D) / L11),"")*1000} -> 78571.429 | O11: {=IFERROR((_xlfn.XLOOKUP(TRIM(F11), TRIM('Database Dapur'!C:C), 'Database Dapur'!D:D) / L11) * G11, "")} -> 3928.5714
F12: Sauce Tomat ABC @5,7 | G12: 350 | H12: Gram | K12: Jrigen | L12: 5700 | M12: {=IFERROR((_xlfn.XLOOKUP(TRIM(F12), TRIM('Database Dapur'!C:C), 'Database Dapur'!D:D)),"")} -> 110391.82 | N12: {=IFERROR((_xlfn.XLOOKUP(TRIM(F12), TRIM('Database Dapur'!C:C), 'Database Dapur'!D:D) / L12),"")*1000} -> 19366.986 | O12: {=IFERROR((_xlfn.XLOOKUP(TRIM(F12), TRIM('Database Dapur'!C:C), 'Database Dapur'!D:D) / L12) * G12, "")} -> 6778.4451
F13: Air | G13: 450 | H13: Gram | M13: {=IFERROR((_xlfn.XLOOKUP(TRIM(F13), TRIM('Database Dapur'!C:C), 'Database Dapur'!D:D)),"")} | N13: {=IFERROR((_xlfn.XLOOKUP(TRIM(F13), TRIM('Database Dapur'!C:C), 'Database Dapur'!D:D) / L13),"")*1000} -> 0 | O13: {=IFERROR((_xlfn.XLOOKUP(TRIM(F13), TRIM('Database Dapur'!C:C), 'Database Dapur'!D:D) / L13) * G13, "")}
B14: =IFERROR(VLOOKUP(A14, 'Database Dapur'!C:D, 2, FALSE),"") | C14: =IFERROR(VLOOKUP(#REF!, 'Database Dapur'!A:D, 3, FALSE),"") | D14: =IFERROR(VLOOKUP(#REF!, 'Database Dapur'!B:E, 3, FALSE),"") | E14: =IFERROR(VLOOKUP(A14, 'Database Dapur'!C:F, 3, FALSE),"") | G14: =SUM(G7:G13) -> 1100 | M14: {=IFERROR((_xlfn.XLOOKUP(TRIM(F14), TRIM('Database Dapur'!C:C), 'Database Dapur'!D:D)),"")} | N14: {=IFERROR((_xlfn.XLOOKUP(TRIM(F14), TRIM('Database Dapur'!C:C), 'Database Dapur'!D:D) / L14),"")*1000} -> 0 | O14: =SUM(O7:O13) -> 15260.176 | U14: =S14-X14 -> 0
A15: Saus Lada Hitam | B15: =IFERROR(VLOOKUP(A15, 'Database Dapur'!C:D, 2, FALSE),"") -> 35000 | C15: =D15*1000 -> 1000 | D15: 1 | E15: =IFERROR(VLOOKUP(A15, 'Database Dapur'!C:F, 3, FALSE),"") -> Kg | F15: Gula Pasir | G15: 75 | H15: Gram | I15: 1000 | J15: Gram | K15: Kg | L15: 1000 | M15: {=IFERROR((_xlfn.XLOOKUP(TRIM(F15), TRIM('Database Dapur'!C:C), 'Database Dapur'!D:D)),"")} -> 17200 | N15: {=IFERROR((_xlfn.XLOOKUP(TRIM(F15), TRIM('Database Dapur'!C:C), 'Database Dapur'!D:D) / L15),"")*1000} -> 17200 | O15: {=IFERROR((_xlfn.XLOOKUP(TRIM(F15), TRIM('Database Dapur'!C:C), 'Database Dapur'!D:D) / L15) * G15, "")} -> 1290 | P15: =O23/I15*C15 -> 30175.363 | Q15: =B15-P15 -> 4824.6369 | R15: =(P15/B15) -> 0.86215323 | S15: =IFERROR(VLOOKUP(A15, 'Database Dapur'!C:D, 2, FALSE),"") -> 35000 | T15: =IFERROR(VLOOKUP(A15, 'Database Dapur'!C:F, 3, FALSE),"") -> Kg | U15: =S15-X15 -> 35000 | V15: =U15-P15 -> 4824.6369 | W15: =(P15/U15) -> 0.86215323
F16: Lada Hitam | G16: 60 | H16: Gram | K16: Kg | L16: 1000 | M16: {=IFERROR((_xlfn.XLOOKUP(TRIM(F16), TRIM('Database Dapur'!C:C), 'Database Dapur'!D:D)),"")} -> 142500 | N16: {=IFERROR((_xlfn.XLOOKUP(TRIM(F16), TRIM('Database Dapur'!C:C), 'Database Dapur'!D:D) / L16),"")*1000} -> 142500 | O16: {=IFERROR((_xlfn.XLOOKUP(TRIM(F16), TRIM('Database Dapur'!C:C), 'Database Dapur'!D:D) / L16) * G16, "")} -> 8550
F17: Maggi @800ml (6) | G17: 65 | H17: Gram | K17: Botol | L17: 800 | M17: {=IFERROR((_xlfn.XLOOKUP(TRIM(F17), TRIM('Database Dapur'!C:C), 'Database Dapur'!D:D)),"")} -> 71583 | N17: {=IFERROR((_xlfn.XLOOKUP(TRIM(F17), TRIM('Database Dapur'!C:C), 'Database Dapur'!D:D) / L17),"")*1000} -> 89478.75 | O17: {=IFERROR((_xlfn.XLOOKUP(TRIM(F17), TRIM('Database Dapur'!C:C), 'Database Dapur'!D:D) / L17) * G17, "")} -> 5816.1187
F18: Ajinomoto @1kg | G18: 50 | H18: Gram | K18: Kg | L18: 1000 | M18: {=IFERROR((_xlfn.XLOOKUP(TRIM(F18), TRIM('Database Dapur'!C:C), 'Database Dapur'!D:D)),"")} -> 44417 | N18: {=IFERROR((_xlfn.XLOOKUP(TRIM(F18), TRIM('Database Dapur'!C:C), 'Database Dapur'!D:D) / L18),"")*1000} -> 44417 | O18: {=IFERROR((_xlfn.XLOOKUP(TRIM(F18), TRIM('Database Dapur'!C:C), 'Database Dapur'!D:D) / L18) * G18, "")} -> 2220.85
F19: Susu UHT @946ml (12) | G19: 160 | H19: Gram | K19: Kg | L19: 1000 | M19: {=IFERROR((_xlfn.XLOOKUP(TRIM(F19), TRIM('Database Dapur'!C:C), 'Database Dapur'!D:D)),"")} -> 17250 | N19: {=IFERROR((_xlfn.XLOOKUP(TRIM(F19), TRIM('Database Dapur'!C:C), 'Database Dapur'!D:D) / L19),"")*1000} -> 17250 | O19: {=IFERROR((_xlfn.XLOOKUP(TRIM(F19), TRIM('Database Dapur'!C:C), 'Database Dapur'!D:D) / L19) * G19, "")} -> 2760
F20: Blue Band @4,5Kg | G20: 60 | H20: Gram | K20: Kg | L20: 1000 | M20: {=IFERROR((_xlfn.XLOOKUP(TRIM(F20), TRIM('Database Dapur'!C:C), 'Database Dapur'!D:D)),"")} -> 29860 | N20: {=IFERROR((_xlfn.XLOOKUP(TRIM(F20), TRIM('Database Dapur'!C:C), 'Database Dapur'!D:D) / L20),"")*1000} -> 29860 | O20: {=IFERROR((_xlfn.XLOOKUP(TRIM(F20), TRIM('Database Dapur'!C:C), 'Database Dapur'!D:D) / L20) * G20, "")} -> 1791.6
F21: Sauce Tomat ABC @5,7 | G21: 400 | H21: Gram | K21: Jrigen | L21: 5700 | M21: {=IFERROR((_xlfn.XLOOKUP(TRIM(F21), TRIM('Database Dapur'!C:C), 'Database Dapur'!D:D)),"")} -> 110391.82 | N21: {=IFERROR((_xlfn.XLOOKUP(TRIM(F21), TRIM('Database Dapur'!C:C), 'Database Dapur'!D:D) / L21),"")*1000} -> 19366.986 | O21: {=IFERROR((_xlfn.XLOOKUP(TRIM(F21), TRIM('Database Dapur'!C:C), 'Database Dapur'!D:D) / L21) * G21, "")} -> 7746.7944
F22: Air | G22: 2500 | H22: Gram | M22: {=IFERROR((_xlfn.XLOOKUP(TRIM(F22), TRIM('Database Dapur'!C:C), 'Database Dapur'!D:D)),"")} | N22: {=IFERROR((_xlfn.XLOOKUP(TRIM(F22), TRIM('Database Dapur'!C:C), 'Database Dapur'!D:D) / L22),"")*1000} -> 0 | O22: {=IFERROR((_xlfn.XLOOKUP(TRIM(F22), TRIM('Database Dapur'!C:C), 'Database Dapur'!D:D) / L22) * G22, "")}
B23: =IFERROR(VLOOKUP(A23, 'Database Dapur'!C:D, 2, FALSE),"") | C23: =IFERROR(VLOOKUP(#REF!, 'Database Dapur'!A:D, 3, FALSE),"") | D23: =IFERROR(VLOOKUP(#REF!, 'Database Dapur'!B:E, 3, FALSE),"") | E23: =IFERROR(VLOOKUP(A23, 'Database Dapur'!C:F, 3, FALSE),"") | G23: =SUM(G15:G22) -> 3370 | M23: {=IFERROR((_xlfn.XLOOKUP(TRIM(F23), TRIM('Database Dapur'!C:C), 'Database Dapur'!D:D)),"")} | N23: {=IFERROR((_xlfn.XLOOKUP(TRIM(F23), TRIM('Database Dapur'!C:C), 'Database Dapur'!D:D) / L23),"")*1000} -> 0 | O23: =SUM(O15:O22) -> 30175.363 | U23: =S23-X23 -> 0
A24: Saus Hot Sapi | B24: =IFERROR(VLOOKUP(A24, 'Database Dapur'!C:D, 2, FALSE),"") -> 38000 | C24: =D24*1000 -> 1000 | D24: 1 | E24: =IFERROR(VLOOKUP(A24, 'Database Dapur'!C:F, 3, FALSE),"") -> Kg | F24: Saus Asam Manis | G24: 160 | H24: Gram | I24: 1000 | J24: Gram | K24: Kg | L24: 1000 | M24: {=IFERROR((_xlfn.XLOOKUP(TRIM(F24), TRIM('Database Dapur'!C:C), 'Database Dapur'!D:D)),"")} -> 27000 | N24: {=IFERROR((_xlfn.XLOOKUP(TRIM(F24), TRIM('Database Dapur'!C:C), 'Database Dapur'!D:D) / L24),"")*1000} -> 27000 | O24: {=IFERROR((_xlfn.XLOOKUP(TRIM(F24), TRIM('Database Dapur'!C:C), 'Database Dapur'!D:D) / L24) * G24, "")} -> 4320 | P24: =O33/I24*C24 -> 31777.796 | Q24: =B24-P24 -> 6222.2041 | R24: =(P24/B24) -> 0.83625779 | S24: =IFERROR(VLOOKUP(A24, 'Database Dapur'!C:D, 2, FALSE),"") -> 38000 | T24: =IFERROR(VLOOKUP(A24, 'Database Dapur'!C:F, 3, FALSE),"") -> Kg | U24: =S24-X24 -> 38000 | V24: =U24-P24 -> 6222.2041 | W24: =(P24/U24) -> 0.83625779
F25: Bawang Putih Cincang | G25: 80 | H25: Gram | K25: Kg | L25: 1000 | M25: {=IFERROR((_xlfn.XLOOKUP(TRIM(F25), TRIM('Database Dapur'!C:C), 'Database Dapur'!D:D)),"")} -> 37000 | N25: {=IFERROR((_xlfn.XLOOKUP(TRIM(F25), TRIM('Database Dapur'!C:C), 'Database Dapur'!D:D) / L25),"")*1000} -> 37000 | O25: {=IFERROR((_xlfn.XLOOKUP(TRIM(F25), TRIM('Database Dapur'!C:C), 'Database Dapur'!D:D) / L25) * G25, "")} -> 2960
F26: Cabe Rawit Kecil | G26: 130 | H26: Gram | K26: Kg | L26: 1000 | M26: {=IFERROR((_xlfn.XLOOKUP(TRIM(F26), TRIM('Database Dapur'!C:C), 'Database Dapur'!D:D)),"")} -> 50000 | N26: {=IFERROR((_xlfn.XLOOKUP(TRIM(F26), TRIM('Database Dapur'!C:C), 'Database Dapur'!D:D) / L26),"")*1000} -> 50000 | O26: {=IFERROR((_xlfn.XLOOKUP(TRIM(F26), TRIM('Database Dapur'!C:C), 'Database Dapur'!D:D) / L26) * G26, "")} -> 6500
F27: My Taste BBQ Spicy Sauce @500gr | G27: 200 | H27: Gram | K27: Pcs | L27: 500 | M27: {=IFERROR((_xlfn.XLOOKUP(TRIM(F27), TRIM('Database Dapur'!C:C), 'Database Dapur'!D:D)),"")} -> 20000 | N27: {=IFERROR((_xlfn.XLOOKUP(TRIM(F27), TRIM('Database Dapur'!C:C), 'Database Dapur'!D:D) / L27),"")*1000} -> 40000 | O27: {=IFERROR((_xlfn.XLOOKUP(TRIM(F27), TRIM('Database Dapur'!C:C), 'Database Dapur'!D:D) / L27) * G27, "")} -> 8000
F28: My Taste Hickory Smoke @500gr | G28: 100 | H28: Gram | K28: Pcs | L28: 500 | M28: {=IFERROR((_xlfn.XLOOKUP(TRIM(F28), TRIM('Database Dapur'!C:C), 'Database Dapur'!D:D)),"")} -> 21300 | N28: {=IFERROR((_xlfn.XLOOKUP(TRIM(F28), TRIM('Database Dapur'!C:C), 'Database Dapur'!D:D) / L28),"")*1000} -> 42600 | O28: {=IFERROR((_xlfn.XLOOKUP(TRIM(F28), TRIM('Database Dapur'!C:C), 'Database Dapur'!D:D) / L28) * G28, "")} -> 4260
F29: Garam | G29: 20 | H29: Gram | K29: Kg | L29: 1000 | M29: {=IFERROR((_xlfn.XLOOKUP(TRIM(F29), TRIM('Database Dapur'!C:C), 'Database Dapur'!D:D)),"")} -> 6100 | N29: {=IFERROR((_xlfn.XLOOKUP(TRIM(F29), TRIM('Database Dapur'!C:C), 'Database Dapur'!D:D) / L29),"")*1000} -> 6100 | O29: {=IFERROR((_xlfn.XLOOKUP(TRIM(F29), TRIM('Database Dapur'!C:C), 'Database Dapur'!D:D) / L29) * G29, "")} -> 122
F30: Ajinomoto @1kg | G30: 20 | H30: Gram | K30: Kg | L30: 1000 | M30: {=IFERROR((_xlfn.XLOOKUP(TRIM(F30), TRIM('Database Dapur'!C:C), 'Database Dapur'!D:D)),"")} -> 44417 | N30: {=IFERROR((_xlfn.XLOOKUP(TRIM(F30), TRIM('Database Dapur'!C:C), 'Database Dapur'!D:D) / L30),"")*1000} -> 44417 | O30: {=IFERROR((_xlfn.XLOOKUP(TRIM(F30), TRIM('Database Dapur'!C:C), 'Database Dapur'!D:D) / L30) * G30, "")} -> 888.34
F31: Sauce Sambal ABC @5,5gr | G31: 180 | H31: Gram | K31: Jrigen | L31: 5500 | M31: {=IFERROR((_xlfn.XLOOKUP(TRIM(F31), TRIM('Database Dapur'!C:C), 'Database Dapur'!D:D)),"")} -> 144450.04 | N31: {=IFERROR((_xlfn.XLOOKUP(TRIM(F31), TRIM('Database Dapur'!C:C), 'Database Dapur'!D:D) / L31),"")*1000} -> 26263.644 | O31: {=IFERROR((_xlfn.XLOOKUP(TRIM(F31), TRIM('Database Dapur'!C:C), 'Database Dapur'!D:D) / L31) * G31, "")} -> 4727.4559
F32: Air | G32: 180 | H32: Gram | M32: {=IFERROR((_xlfn.XLOOKUP(TRIM(F32), TRIM('Database Dapur'!C:C), 'Database Dapur'!D:D)),"")} | N32: {=IFERROR((_xlfn.XLOOKUP(TRIM(F32), TRIM('Database Dapur'!C:C), 'Database Dapur'!D:D) / L32),"")*1000} -> 0 | O32: {=IFERROR((_xlfn.XLOOKUP(TRIM(F32), TRIM('Database Dapur'!C:C), 'Database Dapur'!D:D) / L32) * G32, "")}
B33: =IFERROR(VLOOKUP(A33, 'Database Dapur'!C:D, 2, FALSE),"") | C33: =IFERROR(VLOOKUP(#REF!, 'Database Dapur'!A:D, 3, FALSE),"") | D33: =IFERROR(VLOOKUP(#REF!, 'Database Dapur'!B:E, 3, FALSE),"") | E33: =IFERROR(VLOOKUP(A33, 'Database Dapur'!C:F, 3, FALSE),"") | G33: =SUM(G24:G32) -> 1070 | M33: {=IFERROR((_xlfn.XLOOKUP(TRIM(F33), TRIM('Database Dapur'!C:C), 'Database Dapur'!D:D)),"")} | N33: {=IFERROR((_xlfn.XLOOKUP(TRIM(F33), TRIM('Database Dapur'!C:C), 'Database Dapur'!D:D) / L33),"")*1000} -> 0 | O33: =SUM(O24:O32) -> 31777.796 | U33: =S33-X33 -> 0
A34: Saus Hot Ayam | B34: =IFERROR(VLOOKUP(A34, 'Database Dapur'!C:D, 2, FALSE),"") -> 38000 | C34: =D34*1000 -> 1000 | D34: 1 | E34: =IFERROR(VLOOKUP(A34, 'Database Dapur'!C:F, 3, FALSE),"") -> Kg | F34: Saus Asam Manis | G34: 350 | H34: Gram | I34: 1000 | J34: Gram | K34: Kg | L34: 1000 | M34: {=IFERROR((_xlfn.XLOOKUP(TRIM(F34), TRIM('Database Dapur'!C:C), 'Database Dapur'!D:D)),"")} -> 27000 | N34: {=IFERROR((_xlfn.XLOOKUP(TRIM(F34), TRIM('Database Dapur'!C:C), 'Database Dapur'!D:D) / L34),"")*1000} -> 27000 | O34: {=IFERROR((_xlfn.XLOOKUP(TRIM(F34), TRIM('Database Dapur'!C:C), 'Database Dapur'!D:D) / L34) * G34, "")} -> 9450 | P34: =O42/I34*C34 -> 31108.044 | Q34: =B34-P34 -> 6891.956 | R34: =(P34/B34) -> 0.81863274 | S34: =IFERROR(VLOOKUP(A34, 'Database Dapur'!C:D, 2, FALSE),"") -> 38000 | T34: =IFERROR(VLOOKUP(A34, 'Database Dapur'!C:F, 3, FALSE),"") -> Kg | U34: =S34-X34 -> 38000 | V34: =U34-P34 -> 6891.956 | W34: =(P34/U34) -> 0.81863274
F35: Cabe Rawit Kecil | G35: 80 | H35: Gram | K35: Kg | L35: 1000 | M35: {=IFERROR((_xlfn.XLOOKUP(TRIM(F35), TRIM('Database Dapur'!C:C), 'Database Dapur'!D:D)),"")} -> 50000 | N35: {=IFERROR((_xlfn.XLOOKUP(TRIM(F35), TRIM('Database Dapur'!C:C), 'Database Dapur'!D:D) / L35),"")*1000} -> 50000 | O35: {=IFERROR((_xlfn.XLOOKUP(TRIM(F35), TRIM('Database Dapur'!C:C), 'Database Dapur'!D:D) / L35) * G35, "")} -> 4000
F36: Sauce Hot Lava @6,2kg | G36: 200 | H36: Gram | K36: Pcs | L36: 6200 | M36: {=IFERROR((_xlfn.XLOOKUP(TRIM(F36), TRIM('Database Dapur'!C:C), 'Database Dapur'!D:D)),"")} -> 208800 | N36: {=IFERROR((_xlfn.XLOOKUP(TRIM(F36), TRIM('Database Dapur'!C:C), 'Database Dapur'!D:D) / L36),"")*1000} -> 33677.419 | O36: {=IFERROR((_xlfn.XLOOKUP(TRIM(F36), TRIM('Database Dapur'!C:C), 'Database Dapur'!D:D) / L36) * G36, "")} -> 6735.4839
F37: Sauce Hot Lava Volcano @6,2kg | G37: 200 | H37: Gram | K37: Pcs | L37: 6200 | M37: {=IFERROR((_xlfn.XLOOKUP(TRIM(F37), TRIM('Database Dapur'!C:C), 'Database Dapur'!D:D)),"")} -> 241900 | N37: {=IFERROR((_xlfn.XLOOKUP(TRIM(F37), TRIM('Database Dapur'!C:C), 'Database Dapur'!D:D) / L37),"")*1000} -> 39016.129 | O37: {=IFERROR((_xlfn.XLOOKUP(TRIM(F37), TRIM('Database Dapur'!C:C), 'Database Dapur'!D:D) / L37) * G37, "")} -> 7803.2258
F38: Garam | G38: 8 | H38: Gram | K38: Kg | L38: 1000 | M38: {=IFERROR((_xlfn.XLOOKUP(TRIM(F38), TRIM('Database Dapur'!C:C), 'Database Dapur'!D:D)),"")} -> 6100 | N38: {=IFERROR((_xlfn.XLOOKUP(TRIM(F38), TRIM('Database Dapur'!C:C), 'Database Dapur'!D:D) / L38),"")*1000} -> 6100 | O38: {=IFERROR((_xlfn.XLOOKUP(TRIM(F38), TRIM('Database Dapur'!C:C), 'Database Dapur'!D:D) / L38) * G38, "")} -> 48.8
F39: Ajinomoto @1kg | G39: 10 | H39: Gram | K39: Kg | L39: 1000 | M39: {=IFERROR((_xlfn.XLOOKUP(TRIM(F39), TRIM('Database Dapur'!C:C), 'Database Dapur'!D:D)),"")} -> 44417 | N39: {=IFERROR((_xlfn.XLOOKUP(TRIM(F39), TRIM('Database Dapur'!C:C), 'Database Dapur'!D:D) / L39),"")*1000} -> 44417 | O39: {=IFERROR((_xlfn.XLOOKUP(TRIM(F39), TRIM('Database Dapur'!C:C), 'Database Dapur'!D:D) / L39) * G39, "")} -> 444.17
F40: Sauce Sambal ABC @5,5gr | G40: 100 | H40: Gram | K40: Jrigen | L40: 5500 | M40: {=IFERROR((_xlfn.XLOOKUP(TRIM(F40), TRIM('Database Dapur'!C:C), 'Database Dapur'!D:D)),"")} -> 144450.04 | N40: {=IFERROR((_xlfn.XLOOKUP(TRIM(F40), TRIM('Database Dapur'!C:C), 'Database Dapur'!D:D) / L40),"")*1000} -> 26263.644 | O40: {=IFERROR((_xlfn.XLOOKUP(TRIM(F40), TRIM('Database Dapur'!C:C), 'Database Dapur'!D:D) / L40) * G40, "")} -> 2626.3644
F41: Air | G41: 120 | H41: Gram | M41: {=IFERROR((_xlfn.XLOOKUP(TRIM(F41), TRIM('Database Dapur'!C:C), 'Database Dapur'!D:D)),"")} | N41: {=IFERROR((_xlfn.XLOOKUP(TRIM(F41), TRIM('Database Dapur'!C:C), 'Database Dapur'!D:D) / L41),"")*1000} -> 0 | O41: {=IFERROR((_xlfn.XLOOKUP(TRIM(F41), TRIM('Database Dapur'!C:C), 'Database Dapur'!D:D) / L41) * G41, "")}
B42: =IFERROR(VLOOKUP(A42, 'Database Dapur'!C:D, 2, FALSE),"") | C42: =IFERROR(VLOOKUP(#REF!, 'Database Dapur'!A:D, 3, FALSE),"") | D42: =IFERROR(VLOOKUP(#REF!, 'Database Dapur'!B:E, 3, FALSE),"") | E42: =IFERROR(VLOOKUP(A42, 'Database Dapur'!C:F, 3, FALSE),"") | G42: =SUM(G34:G41) -> 1068 | M42: {=IFERROR((_xlfn.XLOOKUP(TRIM(F42), TRIM('Database Dapur'!C:C), 'Database Dapur'!D:D)),"")} | N42: {=IFERROR((_xlfn.XLOOKUP(TRIM(F42), TRIM('Database Dapur'!C:C), 'Database Dapur'!D:D) / L42),"")*1000} -> 0 | O42: =SUM(O34:O41) -> 31108.044 | U42: =S42-X42 -> 0
A43: Saus Vietnam | B43: =IFERROR(VLOOKUP(A43, 'Database Dapur'!C:D, 2, FALSE),"") -> 31000 | C43: =D43*1000 -> 1000 | D43: 1 | E43: =IFERROR(VLOOKUP(A43, 'Database Dapur'!C:F, 3, FALSE),"") -> Kg | F43: Bawang Putih Cincang | G43: 35 | H43: Gram | I43: 1000 | J43: Gram | K43: Kg | L43: 1000 | M43: {=IFERROR((_xlfn.XLOOKUP(TRIM(F43), TRIM('Database Dapur'!C:C), 'Database Dapur'!D:D)),"")} -> 37000 | N43: {=IFERROR((_xlfn.XLOOKUP(TRIM(F43), TRIM('Database Dapur'!C:C), 'Database Dapur'!D:D) / L43),"")*1000} -> 37000 | O43: {=IFERROR((_xlfn.XLOOKUP(TRIM(F43), TRIM('Database Dapur'!C:C), 'Database Dapur'!D:D) / L43) * G43, "")} -> 1295 | P43: =O58/I43*C43 -> 21028.975 | Q43: =B43-P43 -> 9971.0253 | R43: =(P43/B43) -> 0.67835402 | S43: =IFERROR(VLOOKUP(A43, 'Database Dapur'!C:D, 2, FALSE),"") -> 31000 | T43: =IFERROR(VLOOKUP(A43, 'Database Dapur'!C:F, 3, FALSE),"") -> Kg | U43: =S43-X43 -> 31000 | V43: =U43-P43 -> 9971.0253 | W43: =(P43/U43) -> 0.67835402
...

Sheet Pembungkus
A2: Nama | B2: Kode | C2: Nama | D2: Qty | E2: Satuan
A3: Ice Campur | B3: BKS.30131 | C3: Thinwall Victory | D3: 1 | E3: Pcs
A4: Ice Campur | B4: BKS.30128 | C4: Sendok Garbu | D4: 1 | E4: Pcs
A5: Ice Campur | B5: BKS.30120 | C5: Kresek. 20 | D5: 1 | E5: Pcs
A6: Mie | B6: BKS.30128 | C6: Sendok Garbu | D6: 1 | E6: Pcs
A7: Mie | B7: BKS.30135 | C7: Tutup Paper Bowl | D7: 1 | E7: Pcs
A8: Mie | B8: BKS.30123 | C8: Paper Bowl | D8: 1 | E8: Pcs
A9: Mie | B9: BKS.30120 | C9: Kresek. 20 | D9: 1 | E9: Pcs
A10: Free | B10: FRE.001 | C10: Ice Tea | D10: 1 | E10: Porsi
A11: Free | B11: MNMN.30100 | C11: Air Mineral | D11: 1 | E11: Btl

Sheet Rekap Harga Dapur
A2: Nama | B2: BPP Per Jual | C2: Laba Lama | D2: Persentase Lama | E2: Harga Jual Lama | F2: Satuan | G2: Harga Jual Baru | H2: Laba Baru | I2: Persentase Baru
A3: =IFERROR(__xludf.DUMMYFUNCTION("FILTER({'BPP Dapur'!A7:A1001, 'BPP Dapur'!P7:W1001}, 'BPP Dapur'!A7:A1001<>"""")"),"Saus Asam Manis") -> Saus Asam Manis | B3: =IFERROR(__xludf.DUMMYFUNCTION("""COMPUTED_VALUE"""),15260.17613167534) -> 15260.176 | C3: =IFERROR(__xludf.DUMMYFUNCTION("""COMPUTED_VALUE"""),11739.82386832466) -> 11739.824 | D3: =IFERROR(__xludf.DUMMYFUNCTION("""COMPUTED_VALUE"""),0.5651917085805681) -> 0.56519171 | E3: =IFERROR(__xludf.DUMMYFUNCTION("""COMPUTED_VALUE"""),27000.0) -> 27000 | F3: =IFERROR(__xludf.DUMMYFUNCTION("""COMPUTED_VALUE"""),"Kg") -> Kg | G3: =IFERROR(__xludf.DUMMYFUNCTION("""COMPUTED_VALUE"""),27000.0) -> 27000 | H3: =IFERROR(__xludf.DUMMYFUNCTION("""COMPUTED_VALUE"""),11739.82386832466) -> 11739.824 | I3: =IFERROR(__xludf.DUMMYFUNCTION("""COMPUTED_VALUE"""),0.5651917085805681) -> 0.56519171
A4: =IFERROR(__xludf.DUMMYFUNCTION("""COMPUTED_VALUE"""),"Saus Lada Hitam ") -> Saus Lada Hitam | B4: =IFERROR(__xludf.DUMMYFUNCTION("""COMPUTED_VALUE"""),30175.36313596491) -> 30175.363 | C4: =IFERROR(__xludf.DUMMYFUNCTION("""COMPUTED_VALUE"""),4824.636864035088) -> 4824.6369 | D4: =IFERROR(__xludf.DUMMYFUNCTION("""COMPUTED_VALUE"""),0.8621532324561403) -> 0.86215323 | E4: =IFERROR(__xludf.DUMMYFUNCTION("""COMPUTED_VALUE"""),35000.0) -> 35000 | F4: =IFERROR(__xludf.DUMMYFUNCTION("""COMPUTED_VALUE"""),"Kg") -> Kg | G4: =IFERROR(__xludf.DUMMYFUNCTION("""COMPUTED_VALUE"""),35000.0) -> 35000 | H4: =IFERROR(__xludf.DUMMYFUNCTION("""COMPUTED_VALUE"""),4824.636864035088) -> 4824.6369 | I4: =IFERROR(__xludf.DUMMYFUNCTION("""COMPUTED_VALUE"""),0.8621532324561403) -> 0.86215323
A5: =IFERROR(__xludf.DUMMYFUNCTION("""COMPUTED_VALUE"""),"Saus Hot Sapi") -> Saus Hot Sapi | B5: =IFERROR(__xludf.DUMMYFUNCTION("""COMPUTED_VALUE"""),31777.795854545453) -> 31777.796 | C5: =IFERROR(__xludf.DUMMYFUNCTION("""COMPUTED_VALUE"""),6222.204145454547) -> 6222.2041 | D5: =IFERROR(__xludf.DUMMYFUNCTION("""COMPUTED_VALUE"""),0.836257785645933) -> 0.83625779 | E5: =IFERROR(__xludf.DUMMYFUNCTION("""COMPUTED_VALUE"""),38000.0) -> 38000 | F5: =IFERROR(__xludf.DUMMYFUNCTION("""COMPUTED_VALUE"""),"Kg") -> Kg | G5: =IFERROR(__xludf.DUMMYFUNCTION("""COMPUTED_VALUE"""),38000.0) -> 38000 | H5: =IFERROR(__xludf.DUMMYFUNCTION("""COMPUTED_VALUE"""),6222.204145454547) -> 6222.2041 | I5: =IFERROR(__xludf.DUMMYFUNCTION("""COMPUTED_VALUE"""),0.836257785645933) -> 0.83625779
A6: =IFERROR(__xludf.DUMMYFUNCTION("""COMPUTED_VALUE"""),"Saus Hot Ayam") -> Saus Hot Ayam | B6: =IFERROR(__xludf.DUMMYFUNCTION("""COMPUTED_VALUE"""),31108.044041055717) -> 31108.044 | C6: =IFERROR(__xludf.DUMMYFUNCTION("""COMPUTED_VALUE"""),6891.955958944283) -> 6891.956 | D6: =IFERROR(__xludf.DUMMYFUNCTION("""COMPUTED_VALUE"""),0.8186327379225189) -> 0.81863274 | E6: =IFERROR(__xludf.DUMMYFUNCTION("""COMPUTED_VALUE"""),38000.0) -> 38000 | F6: =IFERROR(__xludf.DUMMYFUNCTION("""COMPUTED_VALUE"""),"Kg") -> Kg | G6: =IFERROR(__xludf.DUMMYFUNCTION("""COMPUTED_VALUE"""),38000.0) -> 38000 | H6: =IFERROR(__xludf.DUMMYFUNCTION("""COMPUTED_VALUE"""),6891.955958944283) -> 6891.956 | I6: =IFERROR(__xludf.DUMMYFUNCTION("""COMPUTED_VALUE"""),0.8186327379225189) -> 0.81863274
A7: =IFERROR(__xludf.DUMMYFUNCTION("""COMPUTED_VALUE"""),"Saus Vietnam") -> Saus Vietnam | B7: =IFERROR(__xludf.DUMMYFUNCTION("""COMPUTED_VALUE"""),21028.974735764237) -> 21028.975 | C7: =IFERROR(__xludf.DUMMYFUNCTION("""COMPUTED_VALUE"""),9971.025264235763) -> 9971.0253 | D7: =IFERROR(__xludf.DUMMYFUNCTION("""COMPUTED_VALUE"""),0.6783540237343302) -> 0.67835402 | E7: =IFERROR(__xludf.DUMMYFUNCTION("""COMPUTED_VALUE"""),31000.0) -> 31000 | F7: =IFERROR(__xludf.DUMMYFUNCTION("""COMPUTED_VALUE"""),"Kg") -> Kg | G7: =IFERROR(__xludf.DUMMYFUNCTION("""COMPUTED_VALUE"""),31000.0) -> 31000 | H7: =IFERROR(__xludf.DUMMYFUNCTION("""COMPUTED_VALUE"""),9971.025264235763) -> 9971.0253 | I7: =IFERROR(__xludf.DUMMYFUNCTION("""COMPUTED_VALUE"""),0.6783540237343302) -> 0.67835402
A8: =IFERROR(__xludf.DUMMYFUNCTION("""COMPUTED_VALUE"""),"Saus Madu") -> Saus Madu | B8: =IFERROR(__xludf.DUMMYFUNCTION("""COMPUTED_VALUE"""),25780.903376942355) -> 25780.903 | C8: =IFERROR(__xludf.DUMMYFUNCTION("""COMPUTED_VALUE"""),12219.096623057645) -> 12219.097 | D8: =IFERROR(__xludf.DUMMYFUNCTION("""COMPUTED_VALUE"""),0.6784448257090093) -> 0.67844483 | E8: =IFERROR(__xludf.DUMMYFUNCTION("""COMPUTED_VALUE"""),38000.0) -> 38000 | F8: =IFERROR(__xludf.DUMMYFUNCTION("""COMPUTED_VALUE"""),"Kg") -> Kg | G8: =IFERROR(__xludf.DUMMYFUNCTION("""COMPUTED_VALUE"""),38000.0) -> 38000 | H8: =IFERROR(__xludf.DUMMYFUNCTION("""COMPUTED_VALUE"""),12219.096623057645) -> 12219.097 | I8: =IFERROR(__xludf.DUMMYFUNCTION("""COMPUTED_VALUE"""),0.6784448257090093) -> 0.67844483
A9: =IFERROR(__xludf.DUMMYFUNCTION("""COMPUTED_VALUE"""),"Sambel Jawa") -> Sambel Jawa | B9: =IFERROR(__xludf.DUMMYFUNCTION("""COMPUTED_VALUE"""),39194.75263400926) -> 39194.753 | C9: =IFERROR(__xludf.DUMMYFUNCTION("""COMPUTED_VALUE"""),5805.247365990741) -> 5805.2474 | D9: =IFERROR(__xludf.DUMMYFUNCTION("""COMPUTED_VALUE"""),0.8709945029779835) -> 0.8709945 | E9: =IFERROR(__xludf.DUMMYFUNCTION("""COMPUTED_VALUE"""),45000.0) -> 45000 | F9: =IFERROR(__xludf.DUMMYFUNCTION("""COMPUTED_VALUE"""),"Kg") -> Kg | G9: =IFERROR(__xludf.DUMMYFUNCTION("""COMPUTED_VALUE"""),45000.0) -> 45000 | H9: =IFERROR(__xludf.DUMMYFUNCTION("""COMPUTED_VALUE"""),5805.247365990741) -> 5805.2474 | I9: =IFERROR(__xludf.DUMMYFUNCTION("""COMPUTED_VALUE"""),0.8709945029779835) -> 0.8709945
A10: =IFERROR(__xludf.DUMMYFUNCTION("""COMPUTED_VALUE"""),"Saus Teriyaki") -> Saus Teriyaki | B10: =IFERROR(__xludf.DUMMYFUNCTION("""COMPUTED_VALUE"""),25564.604393659592) -> 25564.604 | C10: =IFERROR(__xludf.DUMMYFUNCTION("""COMPUTED_VALUE"""),10435.395606340408) -> 10435.396 | D10: =IFERROR(__xludf.DUMMYFUNCTION("""COMPUTED_VALUE"""),0.7101278998238776) -> 0.7101279 | E10: =IFERROR(__xludf.DUMMYFUNCTION("""COMPUTED_VALUE"""),36000.0) -> 36000 | F10: =IFERROR(__xludf.DUMMYFUNCTION("""COMPUTED_VALUE"""),"Kg") -> Kg | G10: =IFERROR(__xludf.DUMMYFUNCTION("""COMPUTED_VALUE"""),36000.0) -> 36000 | H10: =IFERROR(__xludf.DUMMYFUNCTION("""COMPUTED_VALUE"""),10435.395606340408) -> 10435.396 | I10: =IFERROR(__xludf.DUMMYFUNCTION("""COMPUTED_VALUE"""),0.7101278998238776) -> 0.7101279
A11: =IFERROR(__xludf.DUMMYFUNCTION("""COMPUTED_VALUE"""),"Kacang Teriyaki") -> Kacang Teriyaki | B11: =IFERROR(__xludf.DUMMYFUNCTION("""COMPUTED_VALUE"""),0.0) -> 0 | C11: =IFERROR(__xludf.DUMMYFUNCTION("""COMPUTED_VALUE"""),42706.8) -> 42706.8 | D11: =IFERROR(__xludf.DUMMYFUNCTION("""COMPUTED_VALUE"""),0.0) -> 0 | E11: =IFERROR(__xludf.DUMMYFUNCTION("""COMPUTED_VALUE"""),42706.8) -> 42706.8 | F11: =IFERROR(__xludf.DUMMYFUNCTION("""COMPUTED_VALUE"""),"Kg") -> Kg | G11: =IFERROR(__xludf.DUMMYFUNCTION("""COMPUTED_VALUE"""),42706.8) -> 42706.8 | H11: =IFERROR(__xludf.DUMMYFUNCTION("""COMPUTED_VALUE"""),42706.8) -> 42706.8 | I11: =IFERROR(__xludf.DUMMYFUNCTION("""COMPUTED_VALUE"""),0.0) -> 0
A12: =IFERROR(__xludf.DUMMYFUNCTION("""COMPUTED_VALUE"""),"Ayam Fillet Kecil @50gr") -> Ayam Fillet Kecil @50gr | B12: =IFERROR(__xludf.DUMMYFUNCTION("""COMPUTED_VALUE"""),57304.11611111112) -> 57304.116 | C12: =IFERROR(__xludf.DUMMYFUNCTION("""COMPUTED_VALUE"""),5695.883888888879) -> 5695.8839 | D12: =IFERROR(__xludf.DUMMYFUNCTION("""COMPUTED_VALUE"""),0.9095891446208114) -> 0.90958914 | E12: =IFERROR(__xludf.DUMMYFUNCTION("""COMPUTED_VALUE"""),63000.0) -> 63000 | F12: =IFERROR(__xludf.DUMMYFUNCTION("""COMPUTED_VALUE"""),"Kg") -> Kg | G12: =IFERROR(__xludf.DUMMYFUNCTION("""COMPUTED_VALUE"""),63000.0) -> 63000 | H12: =IFERROR(__xludf.DUMMYFUNCTION("""COMPUTED_VALUE"""),5695.883888888879) -> 5695.8839 | I12: =IFERROR(__xludf.DUMMYFUNCTION("""COMPUTED_VALUE"""),0.9095891446208114) -> 0.90958914
A13: =IFERROR(__xludf.DUMMYFUNCTION("""COMPUTED_VALUE"""),"Ayam Rice Bowl @500gr") -> Ayam Rice Bowl @500gr | B13: =IFERROR(__xludf.DUMMYFUNCTION("""COMPUTED_VALUE"""),47526.09426881721) -> 47526.094 | C13: =IFERROR(__xludf.DUMMYFUNCTION("""COMPUTED_VALUE"""),19473.905731182793) -> 19473.906 | D13: =IFERROR(__xludf.DUMMYFUNCTION("""COMPUTED_VALUE"""),0.7093446905793613) -> 0.70934469 | E13: =IFERROR(__xludf.DUMMYFUNCTION("""COMPUTED_VALUE"""),67000.0) -> 67000 | F13: =IFERROR(__xludf.DUMMYFUNCTION("""COMPUTED_VALUE"""),"Kg") -> Kg | G13: =IFERROR(__xludf.DUMMYFUNCTION("""COMPUTED_VALUE"""),67000.0) -> 67000 | H13: =IFERROR(__xludf.DUMMYFUNCTION("""COMPUTED_VALUE"""),19473.905731182793) -> 19473.906 | I13: =IFERROR(__xludf.DUMMYFUNCTION("""COMPUTED_VALUE"""),0.7093446905793613) -> 0.70934469
A14: =IFERROR(__xludf.DUMMYFUNCTION("""COMPUTED_VALUE"""),"Gula Mix (Es campur)") -> Gula Mix (Es campur) | B14: =IFERROR(__xludf.DUMMYFUNCTION("""COMPUTED_VALUE"""),21502.96875) -> 21502.969 | C14: =IFERROR(__xludf.DUMMYFUNCTION("""COMPUTED_VALUE"""),3497.03125) -> 3497.0312 | D14: =IFERROR(__xludf.DUMMYFUNCTION("""COMPUTED_VALUE"""),0.86011875) -> 0.86011875 | E14: =IFERROR(__xludf.DUMMYFUNCTION("""COMPUTED_VALUE"""),25000.0) -> 25000 | F14: =IFERROR(__xludf.DUMMYFUNCTION("""COMPUTED_VALUE"""),"Ltr") -> Ltr | G14: =IFERROR(__xludf.DUMMYFUNCTION("""COMPUTED_VALUE"""),25000.0) -> 25000 | H14: =IFERROR(__xludf.DUMMYFUNCTION("""COMPUTED_VALUE"""),3497.03125) -> 3497.0312 | I14: =IFERROR(__xludf.DUMMYFUNCTION("""COMPUTED_VALUE"""),0.86011875) -> 0.86011875
A15: =IFERROR(__xludf.DUMMYFUNCTION("""COMPUTED_VALUE"""),"Kacang Merah (Matang)") -> Kacang Merah (Matang) | B15: =IFERROR(__xludf.DUMMYFUNCTION("""COMPUTED_VALUE"""),20403.0) -> 20403 | C15: =IFERROR(__xludf.DUMMYFUNCTION("""COMPUTED_VALUE"""),4597.0) -> 4597 | D15: =IFERROR(__xludf.DUMMYFUNCTION("""COMPUTED_VALUE"""),0.81612) -> 0.81612 | E15: =IFERROR(__xludf.DUMMYFUNCTION("""COMPUTED_VALUE"""),25000.0) -> 25000 | F15: =IFERROR(__xludf.DUMMYFUNCTION("""COMPUTED_VALUE"""),"Kg") -> Kg | G15: =IFERROR(__xludf.DUMMYFUNCTION("""COMPUTED_VALUE"""),25000.0) -> 25000 | H15: =IFERROR(__xludf.DUMMYFUNCTION("""COMPUTED_VALUE"""),4597.0) -> 4597 | I15: =IFERROR(__xludf.DUMMYFUNCTION("""COMPUTED_VALUE"""),0.81612) -> 0.81612
A16: =IFERROR(__xludf.DUMMYFUNCTION("""COMPUTED_VALUE"""),"Kacang Hijau (Matang)") -> Kacang Hijau (Matang) | B16: =IFERROR(__xludf.DUMMYFUNCTION("""COMPUTED_VALUE"""),12489.066666666666) -> 12489.067 | C16: =IFERROR(__xludf.DUMMYFUNCTION("""COMPUTED_VALUE"""),5510.933333333334) -> 5510.9333 | D16: =IFERROR(__xludf.DUMMYFUNCTION("""COMPUTED_VALUE"""),0.693837037037037) -> 0.69383704 | E16: =IFERROR(__xludf.DUMMYFUNCTION("""COMPUTED_VALUE"""),18000.0) -> 18000 | F16: =IFERROR(__xludf.DUMMYFUNCTION("""COMPUTED_VALUE"""),"Kg") -> Kg | G16: =IFERROR(__xludf.DUMMYFUNCTION("""COMPUTED_VALUE"""),18000.0) -> 18000 | H16: =IFERROR(__xludf.DUMMYFUNCTION("""COMPUTED_VALUE"""),5510.933333333334) -> 5510.9333 | I16: =IFERROR(__xludf.DUMMYFUNCTION("""COMPUTED_VALUE"""),0.693837037037037) -> 0.69383704
A17: =IFERROR(__xludf.DUMMYFUNCTION("""COMPUTED_VALUE"""),"Toping Ayam Jamur @500gr") -> Toping Ayam Jamur @500gr | B17: =IFERROR(__xludf.DUMMYFUNCTION("""COMPUTED_VALUE"""),26950.27335193512) -> 26950.273 | C17: =IFERROR(__xludf.DUMMYFUNCTION("""COMPUTED_VALUE"""),14549.72664806488) -> 14549.727 | D17: =IFERROR(__xludf.DUMMYFUNCTION("""COMPUTED_VALUE"""),0.6494041771550632) -> 0.64940418 | E17: =IFERROR(__xludf.DUMMYFUNCTION("""COMPUTED_VALUE"""),41500.0) -> 41500 | F17: =IFERROR(__xludf.DUMMYFUNCTION("""COMPUTED_VALUE"""),"500gr") -> 500gr | G17: =IFERROR(__xludf.DUMMYFUNCTION("""COMPUTED_VALUE"""),41500.0) -> 41500 | H17: =IFERROR(__xludf.DUMMYFUNCTION("""COMPUTED_VALUE"""),14549.72664806488) -> 14549.727 | I17: =IFERROR(__xludf.DUMMYFUNCTION("""COMPUTED_VALUE"""),0.6494041771550632) -> 0.64940418
A18: =IFERROR(__xludf.DUMMYFUNCTION("""COMPUTED_VALUE"""),"Toping Ayam Kecap @500gr") -> Toping Ayam Kecap @500gr | B18: =IFERROR(__xludf.DUMMYFUNCTION("""COMPUTED_VALUE"""),28520.76140151515) -> 28520.761 | C18: =IFERROR(__xludf.DUMMYFUNCTION("""COMPUTED_VALUE"""),12979.238598484852) -> 12979.239 | D18: =IFERROR(__xludf.DUMMYFUNCTION("""COMPUTED_VALUE"""),0.687247262687112) -> 0.68724726 | E18: =IFERROR(__xludf.DUMMYFUNCTION("""COMPUTED_VALUE"""),41500.0) -> 41500 | F18: =IFERROR(__xludf.DUMMYFUNCTION("""COMPUTED_VALUE"""),"500gr") -> 500gr | G18: =IFERROR(__xludf.DUMMYFUNCTION("""COMPUTED_VALUE"""),41500.0) -> 41500 | H18: =IFERROR(__xludf.DUMMYFUNCTION("""COMPUTED_VALUE"""),12979.238598484852) -> 12979.239 | I18: =IFERROR(__xludf.DUMMYFUNCTION("""COMPUTED_VALUE"""),0.687247262687112) -> 0.68724726
A19: =IFERROR(__xludf.DUMMYFUNCTION("""COMPUTED_VALUE"""),"Toping Ayam Pedas @500gr") -> Toping Ayam Pedas @500gr | B19: =IFERROR(__xludf.DUMMYFUNCTION("""COMPUTED_VALUE"""),23286.61611785095) -> 23286.616 | C19: =IFERROR(__xludf.DUMMYFUNCTION("""COMPUTED_VALUE"""),11713.38388214905) -> 11713.384 | D19: =IFERROR(__xludf.DUMMYFUNCTION("""COMPUTED_VALUE"""),0.6653318890814557) -> 0.66533189 | E19: =IFERROR(__xludf.DUMMYFUNCTION("""COMPUTED_VALUE"""),35000.0) -> 35000 | F19: =IFERROR(__xludf.DUMMYFUNCTION("""COMPUTED_VALUE"""),"500gr") -> 500gr | G19: =IFERROR(__xludf.DUMMYFUNCTION("""COMPUTED_VALUE"""),35000.0) -> 35000 | H19: =IFERROR(__xludf.DUMMYFUNCTION("""COMPUTED_VALUE"""),11713.38388214905) -> 11713.384 | I19: =IFERROR(__xludf.DUMMYFUNCTION("""COMPUTED_VALUE"""),0.6653318890814557) -> 0.66533189
A20: =IFERROR(__xludf.DUMMYFUNCTION("""COMPUTED_VALUE"""),"Kuah Mie") -> Kuah Mie | B20: =IFERROR(__xludf.DUMMYFUNCTION("""COMPUTED_VALUE"""),9954.01) -> 9954.01 | C20: =IFERROR(__xludf.DUMMYFUNCTION("""COMPUTED_VALUE"""),12045.99) -> 12045.99 | D20: =IFERROR(__xludf.DUMMYFUNCTION("""COMPUTED_VALUE"""),0.452455) -> 0.452455 | E20: =IFERROR(__xludf.DUMMYFUNCTION("""COMPUTED_VALUE"""),22000.0) -> 22000 | F20: =IFERROR(__xludf.DUMMYFUNCTION("""COMPUTED_VALUE"""),"Ltr") -> Ltr | G20: =IFERROR(__xludf.DUMMYFUNCTION("""COMPUTED_VALUE"""),22000.0) -> 22000 | H20: =IFERROR(__xludf.DUMMYFUNCTION("""COMPUTED_VALUE"""),12045.99) -> 12045.99 | I20: =IFERROR(__xludf.DUMMYFUNCTION("""COMPUTED_VALUE"""),0.452455) -> 0.452455
A21: =IFERROR(__xludf.DUMMYFUNCTION("""COMPUTED_VALUE"""),"Mie Basah") -> Mie Basah | B21: =IFERROR(__xludf.DUMMYFUNCTION("""COMPUTED_VALUE"""),1224.7295454545454) -> 1224.7295 | C21: =IFERROR(__xludf.DUMMYFUNCTION("""COMPUTED_VALUE"""),1775.2704545454546) -> 1775.2705 | D21: =IFERROR(__xludf.DUMMYFUNCTION("""COMPUTED_VALUE"""),0.4082431818181818) -> 0.40824318 | E21: =IFERROR(__xludf.DUMMYFUNCTION("""COMPUTED_VALUE"""),3000.0) -> 3000 | F21: =IFERROR(__xludf.DUMMYFUNCTION("""COMPUTED_VALUE"""),"Porsi") -> Porsi | G21: =IFERROR(__xludf.DUMMYFUNCTION("""COMPUTED_VALUE"""),3000.0) -> 3000 | H21: =IFERROR(__xludf.DUMMYFUNCTION("""COMPUTED_VALUE"""),1775.2704545454546) -> 1775.2705 | I21: =IFERROR(__xludf.DUMMYFUNCTION("""COMPUTED_VALUE"""),0.4082431818181818) -> 0.40824318

Sheet Database Resto
B5: Kategori Barang | C5: Kode Barang | E5: Nama Barang | G5: Jenis Barang | K5: Def. Hrg. Jual Satuan #1 | M5: Kts (Semua Gdng) | O5: Nilai Satuan | Q5: Nama Satuan
A6: 1. PAKET
B7: 1. PAKET | C7: PKT.033 | E7: 1. ICE CAMPUR ES | G7: Non Persediaan | K7: 0 | M7: 0 | O7: 0 | Q7: Porsi
B8: 1. PAKET | C8: PKT.0020 | E8: CHIKEN JAVA HONEY SPC | G8: Non Persediaan | K8: 0 | M8: 0 | O8: 0 | Q8: Porsi
B9: 1. PAKET | C9: PKT.0017 | E9: CHICKEN HOT MONSTERS | G9: Non Persediaan | K9: 0 | M9: 0 | O9: 0 | Q9: Porsi
B10: 1. PAKET | C10: PKT.0018 | E10: CHICKEN SWEET SOUR | G10: Non Persediaan | K10: 0 | M10: 0 | O10: 0 | Q10: Porsi
B11: 1. PAKET | C11: PKT.0021 | E11: CHIKEN KATSU | G11: Non Persediaan | K11: 0 | M11: 0 | O11: 0 | Q11: Porsi
B12: 1. PAKET | C12: PKT.017 | E12: HOT MONSTERS BEEF | G12: Non Persediaan | K12: 0 | M12: 0 | O12: 0 | Q12: Porsi
B13: 1. PAKET | C13: PKT.018 | E13: MIE AYAM HOT MONSTERS | G13: Non Persediaan | K13: 0 | M13: 0 | O13: 0 | Q13: Porsi
B14: 1. PAKET | C14: PKT.019 | E14: MIE AYAM JAMUR | G14: Non Persediaan | K14: 0 | M14: 0 | O14: 0 | Q14: Porsi
B15: 1. PAKET | C15: PKT.020 | E15: MIE AYAM KATSU | G15: Non Persediaan | K15: 0 | M15: 0 | O15: 0 | Q15: Porsi
B16: 1. PAKET | C16: PKT.021 | E16: MIE AYAM MONSTERS | G16: Non Persediaan | K16: 0 | M16: 0 | O16: 0 | Q16: Porsi
B17: 1. PAKET | C17: PKT.030 | E17: MIE SAPI MONSTERS | G17: Non Persediaan | K17: 0 | M17: 0 | O17: 0 | Q17: Porsi
B18: 1. PAKET | C18: PKT.018 NEW | E18: MIE AYAM HOT MONSTERS | G18: Grup | K18: 0 | M18: 0 | O18: 0 | Q18: Porsi
... B35: 1. PAKET | C35: PKT.004 | E35: .PAKET D | G35: Non Persediaan | K35: 61900 | M35: 0 | O35: 0 | Q35: Porsi
A36: 10.FROZEN FOOD
B37: 10.FROZEN FOOD | C37: FRF.007 | E37: CHICKEN CAKE ROLL | G37: Non Persediaan | K37: 28000 | M37: 0 | O37: 0 | Q37: Porsi
B38: 10.FROZEN FOOD | C38: FRF.001 | E38: IKAN OLAHAN BENTUK TAHU | G38: Non Persediaan | K38: 22000 | M38: 0 | O38: 0 | Q38: Porsi
B39: 10.FROZEN FOOD | C39: FRF.002 | E39: OTAK OTAK | G39: Non Persediaan | K39: 24500 | M39: 0 | O39: 0 | Q39: Porsi
B40: 10.FROZEN FOOD | C40: FRF.003 | E40: BAKSO IKAN BANDENG | G40: Non Persediaan | K40: 26000 | M40: 0 | O40: 0 | Q40: Porsi
B41: 10.FROZEN FOOD | C41: FRF.004 | E41: IKAN OLAHHAN BENTUK KOTAK | G41: Non Persediaan | K41: 12000 | M41: 0 | O41: 0 | Q41: Porsi
B42: 10.FROZEN FOOD | C42: FRF.005 | E42: IKAN OLAHAN BENTUK SCALLOP | G42: Non Persediaan | K42: 22500 | M42: 0 | O42: 0 | Q42: Porsi
B43: 10.FROZEN FOOD | C43: FRF.006 | E43: BAKSO IKAN ISI AYAM | G43: Non Persediaan | K43: 28500 | M43: 0 | O43: 0 | Q43: Porsi
B44: 10.FROZEN FOOD | C44: FRF.008 | E44: BAKSO IKAN BENTUK BINTANG | G44: Non Persediaan | K44: 12000 | M44: 0 | O44: 0 | Q44: Porsi
A45: 2. RICE BOWL
B46: 2. RICE BOWL | C46: REB.013 | E46: FREE ICE TEA | G46: Non Persediaan | K46: 0 | M46: 0 | O46: 0 | Q46: Porsi
B47: 2. RICE BOWL | C47: REB.014 | E47: FREE MINERAL WATER | G47: Non Persediaan | K47: 0 | M47: 0 | O47: 0 | Q47: Porsi
B48: 2. RICE BOWL | C48: REB.015 | E48: FREE ICE CHOCOLATE | G48: Non Persediaan | K48: 3000 | M48: 0 | O48: 0 | Q48: Porsi
B49: 2. RICE BOWL | C49: REB.001 | E49: SPECIAL MONSTER BEEF | G49: Non Persediaan | K49: 36900 | M49: 0 | O49: 0 | Q49: Porsi
B50: 2. RICE BOWL | C50: REB.008 | E50: CHIKEN KATSU | G50: Non Persediaan | K50: 29900 | M50: 0 | O50: 0 | Q50: Porsi
B51: 2. RICE BOWL | C51: REB.016 | E51: FREE ICE CAMPUR 1 P | G51: Non Persediaan | K51: 10000 | M51: 0 | O51: 0 | Q51: Porsi
B52: 2. RICE BOWL | C52: REB.010 | E52: TAMBAH TELUR | G52: Non Persediaan | K52: 3000 | M52: 0 | O52: 0 | Q52: Porsi
B53: 2. RICE BOWL | C53: REB.009 | E53: TAMBAH NASIH PUTIH | G53: Non Persediaan | K53: 3000 | M53: 0 | O53: 0 | Q53: Porsi
B54: 2. RICE BOWL | C54: REB.012 | E54: HOT MONSTERS BEEF | G54: Non Persediaan | K54: 36900 | M54: 0 | O54: 0 | Q54: Porsi
B55: 2. RICE BOWL | C55: REB.017 | E55: FREE ICE TEA SUSU | G55: Non Persediaan | K55: 3000 | M55: 0 | O55: 0 | Q55: Porsi
B56: 2. RICE BOWL | C56: REB.002 | E56: SMOKED PAPPER BEEF | G56: Non Persediaan | K56: 36900 | M56: 0 | O56: 0 | Q56: Porsi
B57: 2. RICE BOWL | C57: 100036 | E57: CHIKEN STEAK | G57: Non Persediaan | K57: 29900 | M57: 0 | O57: 0
B58: 2. RICE BOWL | C58: REB.004 | E58: CHICKEN TERIYAKI | G58: Non Persediaan | K58: 28900 | M58: 0 | O58: 0 | Q58: Porsi
B59: 2. RICE BOWL | C59: REB.003 | E59: HONEY SAUCE BEEF | G59: Non Persediaan | K59: 36900 | M59: 0 | O59: 0 | Q59: Porsi
B60: 2. RICE BOWL | C60: REB.005 | E60: CHICKEN SWEET SOUR | G60: Non Persediaan | K60: 28900 | M60: 0 | O60: 0 | Q60: Porsi
...

Sheet Database Dapur
A1: NO | B1: KELOMPOK | C1: NAMA BARANG | D1: HARGA
A2: 1 | B2: Makanan | C2: Ayam Fillet Dada(bahan baku) | D2: =(39000+42000+43000)/3 -> 41333.333 | E2: Kg
A3: 2 | B3: Makanan | C3: Ayam Rice Bowl @500gr | D3: 67000 | E3: Kg
A4: 3 | B4: Makanan | C4: Ayam Fillet Kecil @50gr | D4: 63000 | E4: Kg
A5: 4 | B5: Makanan | C5: Toping Ayam Kecap @500gr | D5: 41500 | E5: 500gr
A6: 5 | B6: Makanan | C6: Toping Ayam Jamur @500gr | D6: 41500 | E6: 500gr
A7: 6 | B7: Makanan | C7: Beef Rice Bowl @500gr | D7: 92000 | E7: Kg
A8: 7 | B8: Makanan | C8: Toping Ayam Pedas @500gr | D8: 35000 | E8: 500gr
A9: 8 | B9: Makanan | C9: Saus Japanese | D9: 0 | E9: Kg
A10: 9 | B10: Makanan | C10: Sauce Sambal ABC @24kg | D10: 26765 | E10: Kg
A11: 10 | B11: Makanan | C11: Sauce Tomat ABC @24kg | D11: 17261.5 | E11: Kg
A12: 11 | B12: Makanan | C12: Saus Ayam Danbing | D12: 65000 | E12: Kg
A13: 12 | B13: Makanan | C13: Saus Lada Hitam | D13: 35000 | E13: Kg
A14: 13 | B14: Makanan | C14: Saus Tiga Rasa | D14: 0 | E14: Kg
... A26: 25 | B26: Makanan | C26: Kuah Mie | D26: 22000 | E26: Ltr
A27: 26 | B27: Minuman | C27: Gula Cair | D27: =(14334+14667)/2 -> 14500.5 | E27: Ltr
A28: 27 | B28: Minuman | C28: Kacang Merah (Mentah) | D28: =(42000+43000)/2 -> 42500 | E28: Kg
A29: 28 | B29: Minuman | C29: Kacang Hijau (Mentah) | D29: 31000 | E29: Kg
A30: 29 | B30: Minuman | C30: Kacang Merah (Matang) | D30: 25000 | E30: Kg
A31: 30 | B31: Minuman | C31: Kacang Hijau (Matang) | D31: 18000 | E31: Kg
A32: 31 | B32: Minuman | C32: Skm Carnation @488gr (48) | D32: 14447.3 | E32: kaleng
A33: 32 | B33: Minuman | C33: Teh Bendera @250gr (24) | D33: 8750 | E33: Pcs
A34: 33 | B34: Minuman | C34: Teh Tong Tji @250gr | D34: 17250 | E34: Pcs
A35: 34 | B35: Minuman | C35: Saus Hot Sapi | D35: 38000 | E35: Kg
A36: 35 | B36: Minuman | C36: Nanas | D36: =(13000+12500)/2 -> 12750 | E36: Pcs
A37: 36 | B37: Minuman | C37: Mili Choco Hazelnut @1kg | D37: 60000 | E37: Kg
A38: 37 | B38: Minuman | C38: Teh Bandulan @40gr | D38: 3100 | E38: Pcs
A39: 38 | B39: Minuman | C39: Brown Sugar @1000ml (6) | D39: 105450 | E39: Botol
A40: 39 | B40: Minuman | C40: Gula Mix (Es campur) | D40: 25000 | E40: Ltr
A41: 40 | B41: Minuman | C41: Coklat Mix (bubuk) | D41: 12000 | E41: Kg
A42: 41 | B42: Minuman | C42: Tehh Mix @60gr | D42: 8000 | E42: Pcs
A43: 42 | B43: Pembantu | C43: baking powder (Crascan) @2721 | D43: 0 | E43: Kg
A44: 43 | B44: Pembantu | C44: baking powder hercules @450gr | D44: 46000 | E44: kaleng
A45: 44 | B45: Pembantu | C45: Bawang Putih Cincang | D45: 37000 | E45: Kg
A46: 45 | B46: Pembantu | C46: Bawang Merah | D46: =(43000+44000)/2 -> 43500 | E46: Kg
A47: 46 | B47: Pembantu | C47: Bawang Putih | D47: 0 | E47: Kg
A48: 47 | B48: Pembantu | C48: Cabe Rawit Kecil | D48: 50000 | E48: Kg
A49: 48 | B49: Pembantu | C49: Cabe Merah Besar | D49: 30000 | E49: Kg
A50: 49 | B50: Pembantu | C50: Coklat Batang @500gr | D50: 0 | E50: Kg
A51: 50 | B51: Pembantu | C51: Coklat Bubuk | D51: 0 | E51: Kg
...

Sheet Harga Bpp Resto
A2: Grup | B2: Kode | C2: Nama | D2: Aktif | E2: Harga Nota | F2: Compress | H2: Eccurate | J2: Harga Baru
F3: Harga | G3: Satuan | H3: Harag | I3: Satuan | J3: Harga Baru | K3: Satuan | L3: Up Harga
A4: BB.MKN | B4: MKN.30126 | C4: Mie Basah | E4: 3000 | F4: =H4 -> 3000 | G4: Pcs | H4: =IFERROR(VLOOKUP(B4, 'Database Resto'!C:P, 13, FALSE),"") -> 3000 | I4: =IFERROR(VLOOKUP(B4, 'Database Resto'!C:T, 15, FALSE),"") -> Pcs | K4: =IFERROR(VLOOKUP(B4, 'Database Resto'!C:T, 15, FALSE),"") -> Pcs
A5: BB.MKN | B5: MKN.30127 | C5: Mie Goreng | E5: 3000 | F5: =H5 -> 3000 | G5: Pcs | H5: =IFERROR(VLOOKUP(B5, 'Database Resto'!C:P, 13, FALSE),"") -> 3000 | I5: =IFERROR(VLOOKUP(B5, 'Database Resto'!C:T, 15, FALSE),"") -> Pcs | K5: =IFERROR(VLOOKUP(B5, 'Database Resto'!C:T, 15, FALSE),"") -> Pcs
A6: BB.MKN | B6: MKN.30101 | C6: Ayam Filet | E6: 3150 | F6: =H6 -> 3150 | G6: Pcs | H6: =IFERROR(VLOOKUP(B6, 'Database Resto'!C:P, 13, FALSE),"") -> 3150 | I6: =IFERROR(VLOOKUP(B6, 'Database Resto'!C:T, 15, FALSE),"") -> Pcs | K6: =IFERROR(VLOOKUP(B6, 'Database Resto'!C:T, 15, FALSE),"") -> Pcs
A7: BB.MKN | B7: MKN.30116 | C7: Ice Cream Goreng Coklat | E7: 6000 | F7: =H7 -> 6000 | G7: Pcs | H7: =IFERROR(VLOOKUP(B7, 'Database Resto'!C:P, 13, FALSE),"") -> 6000 | I7: =IFERROR(VLOOKUP(B7, 'Database Resto'!C:T, 15, FALSE),"") -> Pcs | K7: =IFERROR(VLOOKUP(B7, 'Database Resto'!C:T, 15, FALSE),"") -> Pcs
A8: BB.MKN | B8: MKN.30117 | C8: Ice Cream Goreng Strawberry | E8: 6000 | F8: =H8 -> 6000 | G8: Pcs | H8: =IFERROR(VLOOKUP(B8, 'Database Resto'!C:P, 13, FALSE),"") -> 6000 | I8: =IFERROR(VLOOKUP(B8, 'Database Resto'!C:T, 15, FALSE),"") -> Pcs | K8: =IFERROR(VLOOKUP(B8, 'Database Resto'!C:T, 15, FALSE),"") -> Pcs
A9: BB.MKN | B9: MKN.30118 | C9: Ice Cream Goreng Vanilla | E9: 6000 | F9: =H9 -> 6000 | G9: Pcs | H9: =IFERROR(VLOOKUP(B9, 'Database Resto'!C:P, 13, FALSE),"") -> 6000 | I9: =IFERROR(VLOOKUP(B9, 'Database Resto'!C:T, 15, FALSE),"") -> Pcs | K9: =IFERROR(VLOOKUP(B9, 'Database Resto'!C:T, 15, FALSE),"") -> Pcs
A10: BB.MNM | B10: MNMN.30112 | C10: K. Hijau | E10: 18000 | F10: =H10*1000 -> 18000 | G10: Kg | H10: =IFERROR(VLOOKUP(B10, 'Database Resto'!C:P, 13, FALSE),"") -> 18 | I10: =IFERROR(VLOOKUP(B10, 'Database Resto'!C:T, 15, FALSE),"") -> Gram | K10: =IFERROR(VLOOKUP(B10, 'Database Resto'!C:T, 15, FALSE),"") -> Gram
A11: BB.MNM | B11: MNMN.30113 | C11: K. Merah | E11: 25000 | F11: =H11*1000 -> 25000 | G11: Kg | H11: =IFERROR(VLOOKUP(B11, 'Database Resto'!C:P, 13, FALSE),"") -> 25 | I11: =IFERROR(VLOOKUP(B11, 'Database Resto'!C:T, 15, FALSE),"") -> Gram | K11: =IFERROR(VLOOKUP(B11, 'Database Resto'!C:T, 15, FALSE),"") -> Gram
A12: BB.MNM | B12: MNMN.30109 | C12: Gula Es Campur | E12: 25000 | F12: =H12*1000 -> 25000 | G12: Kg | H12: =IFERROR(VLOOKUP(B12, 'Database Resto'!C:P, 13, FALSE),"") -> 25 | I12: =IFERROR(VLOOKUP(B12, 'Database Resto'!C:T, 15, FALSE),"") -> Gram | K12: =IFERROR(VLOOKUP(B12, 'Database Resto'!C:T, 15, FALSE),"") -> Gram
A13: BB.MKN | B13: MKN.30134 | C13: S. Asam Manis | E13: 27000 | F13: =H13*1000 -> 27000 | G13: Kg | H13: =IFERROR(VLOOKUP(B13, 'Database Resto'!C:P, 13, FALSE),"") -> 27 | I13: =IFERROR(VLOOKUP(B13, 'Database Resto'!C:T, 15, FALSE),"") -> Gram | K13: =IFERROR(VLOOKUP(B13, 'Database Resto'!C:T, 15, FALSE),"") -> Gram
A14: BB.MKN | B14: MKN.30143 | C14: S. Vietnam | E14: 31000 | F14: =H14*1000 -> 31366.922 | G14: Kg | H14: =IFERROR(VLOOKUP(B14, 'Database Resto'!C:P, 13, FALSE),"") -> 31.366922 | I14: =IFERROR(VLOOKUP(B14, 'Database Resto'!C:T, 15, FALSE),"") -> Gram | K14: =IFERROR(VLOOKUP(B14, 'Database Resto'!C:T, 15, FALSE),"") -> Gram
A15: BB.MKN | B15: MKN.30135 | C15: S. Ayam Pedas | E15: 38000 | F15: =H15*1000 -> 38000 | G15: Kg | H15: =IFERROR(VLOOKUP(B15, 'Database Resto'!C:P, 13, FALSE),"") -> 38 | I15: =IFERROR(VLOOKUP(B15, 'Database Resto'!C:T, 15, FALSE),"") -> Gram | K15: =IFERROR(VLOOKUP(B15, 'Database Resto'!C:T, 15, FALSE),"") -> Gram
